[2024-10-25T11:15:13.254+0000] {taskinstance.py:1159} INFO - Dependencies all met for dep_context=non-requeueable deps ti=<TaskInstance: check_db_connection.check_connection manual__2024-10-25T11:15:12.180093+00:00 [queued]>
[2024-10-25T11:15:13.264+0000] {taskinstance.py:1159} INFO - Dependencies all met for dep_context=requeueable deps ti=<TaskInstance: check_db_connection.check_connection manual__2024-10-25T11:15:12.180093+00:00 [queued]>
[2024-10-25T11:15:13.265+0000] {taskinstance.py:1361} INFO - Starting attempt 1 of 2
[2024-10-25T11:15:13.280+0000] {taskinstance.py:1382} INFO - Executing <Task(SQLExecuteQueryOperator): check_connection> on 2024-10-25 11:15:12.180093+00:00
[2024-10-25T11:15:13.293+0000] {standard_task_runner.py:57} INFO - Started process 67 to run task
[2024-10-25T11:15:13.302+0000] {standard_task_runner.py:84} INFO - Running: ['***', 'tasks', 'run', 'check_db_connection', 'check_connection', 'manual__2024-10-25T11:15:12.180093+00:00', '--job-id', '43', '--raw', '--subdir', 'DAGS_FOLDER/dag.py', '--cfg-path', '/tmp/tmpc_imqvrq']
[2024-10-25T11:15:13.326+0000] {standard_task_runner.py:85} INFO - Job 43: Subtask check_connection
[2024-10-25T11:15:13.404+0000] {task_command.py:416} INFO - Running <TaskInstance: check_db_connection.check_connection manual__2024-10-25T11:15:12.180093+00:00 [running]> on host a6c36815a6df
[2024-10-25T11:15:13.542+0000] {taskinstance.py:1662} INFO - Exporting env vars: AIRFLOW_CTX_DAG_OWNER='***' AIRFLOW_CTX_DAG_ID='check_db_connection' AIRFLOW_CTX_TASK_ID='check_connection' AIRFLOW_CTX_EXECUTION_DATE='2024-10-25T11:15:12.180093+00:00' AIRFLOW_CTX_TRY_NUMBER='1' AIRFLOW_CTX_DAG_RUN_ID='manual__2024-10-25T11:15:12.180093+00:00'
[2024-10-25T11:15:13.543+0000] {sql.py:274} INFO - Executing: create table lol (id int);
[2024-10-25T11:15:13.551+0000] {base.py:73} INFO - Using connection ID 'your_postgres_connection_id' for task execution.
[2024-10-25T11:15:13.561+0000] {base.py:73} INFO - Using connection ID 'your_postgres_connection_id' for task execution.
[2024-10-25T11:15:13.566+0000] {sql.py:418} INFO - Running statement: create table lol (id int);, parameters: None
[2024-10-25T11:15:13.567+0000] {taskinstance.py:1937} ERROR - Task failed with exception
Traceback (most recent call last):
  File "/home/airflow/.local/lib/python3.8/site-packages/airflow/providers/common/sql/operators/sql.py", line 280, in execute
    output = hook.run(
  File "/home/airflow/.local/lib/python3.8/site-packages/airflow/providers/common/sql/hooks/sql.py", line 392, in run
    self._run_command(cur, sql_statement, parameters)
  File "/home/airflow/.local/lib/python3.8/site-packages/airflow/providers/common/sql/hooks/sql.py", line 423, in _run_command
    cur.execute(sql_statement)
psycopg2.errors.DuplicateTable: relation "lol" already exists

[2024-10-25T11:15:13.575+0000] {taskinstance.py:1400} INFO - Marking task as UP_FOR_RETRY. dag_id=check_db_connection, task_id=check_connection, execution_date=20241025T111512, start_date=20241025T111513, end_date=20241025T111513
[2024-10-25T11:15:13.590+0000] {standard_task_runner.py:104} ERROR - Failed to execute job 43 for task check_connection (relation "lol" already exists
; 67)
[2024-10-25T11:15:13.596+0000] {local_task_job_runner.py:228} INFO - Task exited with return code 1
[2024-10-25T11:15:13.612+0000] {taskinstance.py:2778} INFO - 0 downstream tasks scheduled from follow-on schedule check
