[2024-10-27T13:24:08.712+0000] {taskinstance.py:1159} INFO - Dependencies all met for dep_context=non-requeueable deps ti=<TaskInstance: sql_extract_outrrrrr.save_to_csv_task manual__2024-10-27T13:24:04.896858+00:00 [queued]>
[2024-10-27T13:24:08.723+0000] {taskinstance.py:1159} INFO - Dependencies all met for dep_context=requeueable deps ti=<TaskInstance: sql_extract_outrrrrr.save_to_csv_task manual__2024-10-27T13:24:04.896858+00:00 [queued]>
[2024-10-27T13:24:08.723+0000] {taskinstance.py:1361} INFO - Starting attempt 1 of 1
[2024-10-27T13:24:08.744+0000] {taskinstance.py:1382} INFO - Executing <Task(PythonOperator): save_to_csv_task> on 2024-10-27 13:24:04.896858+00:00
[2024-10-27T13:24:08.749+0000] {standard_task_runner.py:57} INFO - Started process 556 to run task
[2024-10-27T13:24:08.755+0000] {standard_task_runner.py:84} INFO - Running: ['***', 'tasks', 'run', 'sql_extract_outrrrrr', 'save_to_csv_task', 'manual__2024-10-27T13:24:04.896858+00:00', '--job-id', '77', '--raw', '--subdir', 'DAGS_FOLDER/ggg.py', '--cfg-path', '/tmp/tmpe3swpohn']
[2024-10-27T13:24:08.759+0000] {standard_task_runner.py:85} INFO - Job 77: Subtask save_to_csv_task
[2024-10-27T13:24:08.802+0000] {task_command.py:416} INFO - Running <TaskInstance: sql_extract_outrrrrr.save_to_csv_task manual__2024-10-27T13:24:04.896858+00:00 [running]> on host d556bcf16473
[2024-10-27T13:24:09.027+0000] {taskinstance.py:1662} INFO - Exporting env vars: AIRFLOW_CTX_DAG_OWNER='***' AIRFLOW_CTX_DAG_ID='sql_extract_outrrrrr' AIRFLOW_CTX_TASK_ID='save_to_csv_task' AIRFLOW_CTX_EXECUTION_DATE='2024-10-27T13:24:04.896858+00:00' AIRFLOW_CTX_TRY_NUMBER='1' AIRFLOW_CTX_DAG_RUN_ID='manual__2024-10-27T13:24:04.896858+00:00'
[2024-10-27T13:24:09.037+0000] {taskinstance.py:1937} ERROR - Task failed with exception
Traceback (most recent call last):
  File "/home/airflow/.local/lib/python3.8/site-packages/airflow/operators/python.py", line 192, in execute
    return_value = self.execute_callable()
  File "/home/airflow/.local/lib/python3.8/site-packages/airflow/operators/python.py", line 209, in execute_callable
    return self.python_callable(*self.op_args, **self.op_kwargs)
  File "/opt/airflow/dags/ggg.py", line 103, in save_to_csv
    for title, records in all_data.items():
AttributeError: 'NoneType' object has no attribute 'items'
[2024-10-27T13:24:09.047+0000] {taskinstance.py:1400} INFO - Marking task as FAILED. dag_id=sql_extract_outrrrrr, task_id=save_to_csv_task, execution_date=20241027T132404, start_date=20241027T132408, end_date=20241027T132409
[2024-10-27T13:24:09.060+0000] {standard_task_runner.py:104} ERROR - Failed to execute job 77 for task save_to_csv_task ('NoneType' object has no attribute 'items'; 556)
[2024-10-27T13:24:09.088+0000] {local_task_job_runner.py:228} INFO - Task exited with return code 1
[2024-10-27T13:24:09.105+0000] {taskinstance.py:2778} INFO - 0 downstream tasks scheduled from follow-on schedule check
