[2024-10-26T06:05:39.409+0000] {taskinstance.py:1159} INFO - Dependencies all met for dep_context=non-requeueable deps ti=<TaskInstance: ssh_log_analysis.analyze_logs manual__2024-10-26T06:05:37.707806+00:00 [queued]>
[2024-10-26T06:05:39.417+0000] {taskinstance.py:1159} INFO - Dependencies all met for dep_context=requeueable deps ti=<TaskInstance: ssh_log_analysis.analyze_logs manual__2024-10-26T06:05:37.707806+00:00 [queued]>
[2024-10-26T06:05:39.417+0000] {taskinstance.py:1361} INFO - Starting attempt 1 of 2
[2024-10-26T06:05:39.430+0000] {taskinstance.py:1382} INFO - Executing <Task(PythonOperator): analyze_logs> on 2024-10-26 06:05:37.707806+00:00
[2024-10-26T06:05:39.434+0000] {standard_task_runner.py:57} INFO - Started process 112 to run task
[2024-10-26T06:05:39.436+0000] {standard_task_runner.py:84} INFO - Running: ['***', 'tasks', 'run', 'ssh_log_analysis', 'analyze_logs', 'manual__2024-10-26T06:05:37.707806+00:00', '--job-id', '54', '--raw', '--subdir', 'DAGS_FOLDER/DAG_log_file_analysis.py', '--cfg-path', '/tmp/tmp39vhfpww']
[2024-10-26T06:05:39.437+0000] {standard_task_runner.py:85} INFO - Job 54: Subtask analyze_logs
[2024-10-26T06:05:39.479+0000] {task_command.py:416} INFO - Running <TaskInstance: ssh_log_analysis.analyze_logs manual__2024-10-26T06:05:37.707806+00:00 [running]> on host 896c7dbfaa8f
[2024-10-26T06:05:39.546+0000] {taskinstance.py:1662} INFO - Exporting env vars: AIRFLOW_CTX_DAG_OWNER='getroller' AIRFLOW_CTX_DAG_ID='ssh_log_analysis' AIRFLOW_CTX_TASK_ID='analyze_logs' AIRFLOW_CTX_EXECUTION_DATE='2024-10-26T06:05:37.707806+00:00' AIRFLOW_CTX_TRY_NUMBER='1' AIRFLOW_CTX_DAG_RUN_ID='manual__2024-10-26T06:05:37.707806+00:00'
[2024-10-26T06:05:39.546+0000] {taskinstance.py:1937} ERROR - Task failed with exception
Traceback (most recent call last):
  File "/home/airflow/.local/lib/python3.8/site-packages/airflow/operators/python.py", line 192, in execute
    return_value = self.execute_callable()
  File "/home/airflow/.local/lib/python3.8/site-packages/airflow/operators/python.py", line 209, in execute_callable
    return self.python_callable(*self.op_args, **self.op_kwargs)
  File "/opt/airflow/dags/DAG_log_file_analysis.py", line 19, in analyze_logs
    with open(log_file, 'r') as f:
FileNotFoundError: [Errno 2] No such file or directory: 'test-task/openssh.log'
[2024-10-26T06:05:39.555+0000] {taskinstance.py:1400} INFO - Marking task as UP_FOR_RETRY. dag_id=ssh_log_analysis, task_id=analyze_logs, execution_date=20241026T060537, start_date=20241026T060539, end_date=20241026T060539
[2024-10-26T06:05:39.569+0000] {standard_task_runner.py:104} ERROR - Failed to execute job 54 for task analyze_logs ([Errno 2] No such file or directory: 'test-task/openssh.log'; 112)
[2024-10-26T06:05:39.608+0000] {local_task_job_runner.py:228} INFO - Task exited with return code 1
[2024-10-26T06:05:39.625+0000] {taskinstance.py:2778} INFO - 0 downstream tasks scheduled from follow-on schedule check
